<?xml version="1.0" ?>
<!-- =================================================================================== -->
<!-- |    This document was autogenerated by xacro from dual_arm.urdf.xacro            | -->
<!-- |    EDITING THIS FILE BY HAND IS NOT RECOMMENDED                                 | -->
<!-- =================================================================================== -->
<robot name="dual_arm">
  <link name="base_link">
    <visual>
      <origin rpy="0 0 0" xyz="0 0 0"/>
      <geometry>
        <mesh filename="package://asystr_dual_arm_model/meshes/visual/ati_vehicle.dae" scale="0.0018 0.0018 0.0018"/>
      </geometry>
    </visual>
    <collision>
      <origin rpy="0 0 0" xyz="0 0 0"/>
      <geometry>
        <mesh filename="package://asystr_dual_arm_model/meshes/collision/ati_vehicle.stl" scale="0.0018 0.0018 0.0018"/>
      </geometry>
    </collision>
  </link>
  <!-- Import dependency files -->
  <!-- Import dependency files -->
  <!-- Create Links -->
  <link name="left_base_link">
    <visual>
      <origin rpy="0 0 0" xyz="0 0 0"/>
      <geometry>
        <mesh filename="package://asystr_sensible_model/meshes/visual/asystr_sensible/base_link.dae" scale="0.001 0.001 0.001"/>
      </geometry>
    </visual>
    <collision>
      <origin rpy="0 0 0" xyz="0 0 0"/>
      <geometry>
        <mesh filename="package://asystr_sensible_model/meshes/collision/asystr_sensible/base_link.stl" scale="0.001 0.001 0.001"/>
      </geometry>
    </collision>
    <inertial>
      <origin rpy="0 0 0" xyz="0 0 0"/>
      <mass value="0.01"/>
      <inertia ixx="0.01" ixy="0.0" ixz="0.0" iyy="0.01" iyz="0.0" izz="0.01"/>
    </inertial>
  </link>
  <link name="left_link_1">
    <visual>
      <origin rpy="0 0 0" xyz="0 0 0"/>
      <geometry>
        <mesh filename="package://asystr_sensible_model/meshes/visual/asystr_sensible/link_1.dae" scale="0.001 0.001 0.001"/>
      </geometry>
    </visual>
    <collision>
      <origin rpy="0 0 0" xyz="0 0 0"/>
      <geometry>
        <mesh filename="package://asystr_sensible_model/meshes/collision/asystr_sensible/link_1.stl" scale="0.001 0.001 0.001"/>
      </geometry>
    </collision>
    <inertial>
      <origin rpy="0 0 0" xyz="0 0 0"/>
      <mass value="0.01"/>
      <inertia ixx="0.01" ixy="0.0" ixz="0.0" iyy="0.01" iyz="0.0" izz="0.01"/>
    </inertial>
  </link>
  <link name="left_link_2">
    <visual>
      <origin rpy="0 0 0" xyz="0 0 0"/>
      <geometry>
        <mesh filename="package://asystr_sensible_model/meshes/visual/asystr_sensible/link_2.dae" scale="0.001 0.001 0.001"/>
      </geometry>
    </visual>
    <collision>
      <origin rpy="0 0 0" xyz="0 0 0"/>
      <geometry>
        <mesh filename="package://asystr_sensible_model/meshes/collision/asystr_sensible/link_2.stl" scale="0.001 0.001 0.001"/>
      </geometry>
    </collision>
    <inertial>
      <origin rpy="0 0 0" xyz="0 0 0"/>
      <mass value="0.01"/>
      <inertia ixx="0.01" ixy="0.0" ixz="0.0" iyy="0.01" iyz="0.0" izz="0.01"/>
    </inertial>
  </link>
  <link name="left_link_3">
    <visual>
      <origin rpy="0 0 0" xyz="0 0 0"/>
      <geometry>
        <mesh filename="package://asystr_sensible_model/meshes/visual/asystr_sensible/link_3.dae" scale="0.001 0.001 0.001"/>
      </geometry>
    </visual>
    <collision>
      <origin rpy="0 0 0" xyz="0 0 0"/>
      <geometry>
        <mesh filename="package://asystr_sensible_model/meshes/collision/asystr_sensible/link_3.stl" scale="0.001 0.001 0.001"/>
      </geometry>
    </collision>
    <inertial>
      <origin rpy="0 0 0" xyz="0 0 0"/>
      <mass value="0.01"/>
      <inertia ixx="0.01" ixy="0.0" ixz="0.0" iyy="0.01" iyz="0.0" izz="0.01"/>
    </inertial>
  </link>
  <link name="left_wrist_adapter">
    <visual>
      <origin rpy="0 0 0" xyz="0 0 0"/>
      <geometry>
        <mesh filename="package://asystr_sensible_model/meshes/visual/RPR/wrist_adapter.dae" scale="0.001 0.001 0.001"/>
      </geometry>
    </visual>
    <collision>
      <origin rpy="0 0 0" xyz="0 0 0"/>
      <geometry>
        <mesh filename="package://asystr_sensible_model/meshes/collision/RPR/wrist_adapter.stl" scale="0.001 0.001 0.001"/>
      </geometry>
    </collision>
    <inertial>
      <origin rpy="0 0 0" xyz="0 0 0"/>
      <mass value="0.01"/>
      <inertia ixx="0.01" ixy="0.0" ixz="0.0" iyy="0.01" iyz="0.0" izz="0.01"/>
    </inertial>
  </link>
  <!-- Create Joints -->
  <joint name="left_joint_1" type="revolute">
    <parent link="left_base_link"/>
    <child link="left_link_1"/>
    <origin rpy="0 0.0 0.0" xyz="0 -0.0 0.2592"/>
    <axis xyz="0 0 1"/>
    <limit effort="100.0" lower="-3.141592653589793" upper="3.141592653589793" velocity="100.0"/>
  </joint>
  <joint name="left_joint_2" type="revolute">
    <parent link="left_link_1"/>
    <child link="left_link_2"/>
    <origin rpy="1.5707963 -1.5707962999999996 4.2089324414645615e-08" xyz="0 0.0 0.0"/>
    <axis xyz="0 0 1"/>
    <limit effort="100.0" lower="-2.0943951023931953" upper="1.5707963267948966" velocity="100.0"/>
  </joint>
  <joint name="left_joint_3" type="revolute">
    <parent link="left_link_2"/>
    <child link="left_link_3"/>
    <origin rpy="0 0.0 -1.5707963" xyz="0.45 0.0 0.0"/>
    <axis xyz="0 0 1"/>
    <limit effort="100.0" lower="0.0" upper="3.141592653589793" velocity="100.0"/>
  </joint>
  <joint name="left_wrist_frame" type="fixed">
    <parent link="left_link_3"/>
    <child link="left_wrist_adapter"/>
    <origin rpy="1.5707963 1.5707962999999996 -4.2089324414645615e-08" xyz="0.117 -0.3299999999999999 8.84231587305945e-09"/>
  </joint>
  <!-- Create Links -->
  <link name="left_link_4">
    <visual>
      <origin rpy="0 0 0" xyz="0 0 0"/>
      <geometry>
        <mesh filename="package://asystr_sensible_model/meshes/visual/RPR/differential.dae" scale="0.001 0.001 0.001"/>
      </geometry>
    </visual>
    <collision>
      <origin rpy="0 0 0" xyz="0 0 0"/>
      <geometry>
        <mesh filename="package://asystr_sensible_model/meshes/collision/RPR/differential.stl" scale="0.001 0.001 0.001"/>
      </geometry>
    </collision>
    <inertial>
      <origin rpy="0 0 0" xyz="0 0 0"/>
      <mass value="0.01"/>
      <inertia ixx="0.01" ixy="0.0" ixz="0.0" iyy="0.01" iyz="0.0" izz="0.01"/>
    </inertial>
  </link>
  <link name="left_link_5">
    <inertial>
      <origin rpy="0 0 0" xyz="0 0 0"/>
      <mass value="0.01"/>
      <inertia ixx="0.01" ixy="0.0" ixz="0.0" iyy="0.01" iyz="0.0" izz="0.01"/>
    </inertial>
  </link>
  <link name="left_link_6">
    <visual>
      <origin rpy="0 0 0" xyz="0 0 0"/>
      <geometry>
        <mesh filename="package://asystr_sensible_model/meshes/visual/RPR/flange.dae" scale="0.001 0.001 0.001"/>
      </geometry>
    </visual>
    <collision>
      <origin rpy="0 0 0" xyz="0 0 0"/>
      <geometry>
        <mesh filename="package://asystr_sensible_model/meshes/collision/RPR/flange.stl" scale="0.001 0.001 0.001"/>
      </geometry>
    </collision>
    <inertial>
      <origin rpy="0 0 0" xyz="0 0 0"/>
      <mass value="0.01"/>
      <inertia ixx="0.01" ixy="0.0" ixz="0.0" iyy="0.01" iyz="0.0" izz="0.01"/>
    </inertial>
  </link>
  <!-- Create Joints -->
  <joint name="left_joint_4" type="revolute">
    <parent link="left_wrist_adapter"/>
    <child link="left_link_4"/>
    <origin rpy="0 -0.0 1.5707963" xyz="0 -0.0 0.08"/>
    <axis xyz="0 0 1"/>
    <limit effort="100.0" lower="-3.141592653589793" upper="3.141592653589793" velocity="100.0"/>
  </joint>
  <joint name="left_joint_5" type="revolute">
    <parent link="left_link_4"/>
    <child link="left_link_5"/>
    <origin rpy="1.5707963 0.0 0.0" xyz="0 0.0 0.0"/>
    <axis xyz="0 0 1"/>
    <limit effort="100.0" lower="-1.5707963267948966" upper="1.5707963267948966" velocity="100.0"/>
  </joint>
  <joint name="left_joint_6" type="revolute">
    <parent link="left_link_5"/>
    <child link="left_link_6"/>
    <origin rpy="-1.5707963 -0.0 0.0" xyz="0 0.04999999999999999 1.3397448292514317e-09"/>
    <axis xyz="0 0 1"/>
    <limit effort="100.0" lower="-3.141592653589793" upper="3.141592653589793" velocity="100.0"/>
  </joint>
  <joint name="base_to_left" type="fixed">
    <parent link="base_link"/>
    <child link="left_base_link"/>
    <origin rpy="3.141592653589793 0 0" xyz="0.76 0.28 1.475"/>
  </joint>
  <!-- Import dependency files -->
  <!-- Import dependency files -->
  <!-- Create Links -->
  <link name="right_base_link">
    <visual>
      <origin rpy="0 0 0" xyz="0 0 0"/>
      <geometry>
        <mesh filename="package://asystr_sensible_model/meshes/visual/asystr_sensible/base_link.dae" scale="0.001 -0.001 0.001"/>
      </geometry>
    </visual>
    <collision>
      <origin rpy="0 0 0" xyz="0 0 0"/>
      <geometry>
        <mesh filename="package://asystr_sensible_model/meshes/collision/asystr_sensible/base_link.stl" scale="0.001 -0.001 0.001"/>
      </geometry>
    </collision>
    <inertial>
      <origin rpy="0 0 0" xyz="0 0 0"/>
      <mass value="0.01"/>
      <inertia ixx="0.01" ixy="0.0" ixz="0.0" iyy="0.01" iyz="0.0" izz="0.01"/>
    </inertial>
  </link>
  <link name="right_link_1">
    <visual>
      <origin rpy="0 0 0" xyz="0 0 0"/>
      <geometry>
        <mesh filename="package://asystr_sensible_model/meshes/visual/asystr_sensible/link_1.dae" scale="0.001 -0.001 0.001"/>
      </geometry>
    </visual>
    <collision>
      <origin rpy="0 0 0" xyz="0 0 0"/>
      <geometry>
        <mesh filename="package://asystr_sensible_model/meshes/collision/asystr_sensible/link_1.stl" scale="0.001 -0.001 0.001"/>
      </geometry>
    </collision>
    <inertial>
      <origin rpy="0 0 0" xyz="0 0 0"/>
      <mass value="0.01"/>
      <inertia ixx="0.01" ixy="0.0" ixz="0.0" iyy="0.01" iyz="0.0" izz="0.01"/>
    </inertial>
  </link>
  <link name="right_link_2">
    <visual>
      <origin rpy="0 0 0" xyz="0 0 0"/>
      <geometry>
        <mesh filename="package://asystr_sensible_model/meshes/visual/asystr_sensible/link_2.dae" scale="0.001 0.001 -0.001"/>
      </geometry>
    </visual>
    <collision>
      <origin rpy="0 0 0" xyz="0 0 0"/>
      <geometry>
        <mesh filename="package://asystr_sensible_model/meshes/collision/asystr_sensible/link_2.stl" scale="0.001 0.001 -0.001"/>
      </geometry>
    </collision>
    <inertial>
      <origin rpy="0 0 0" xyz="0 0 0"/>
      <mass value="0.01"/>
      <inertia ixx="0.01" ixy="0.0" ixz="0.0" iyy="0.01" iyz="0.0" izz="0.01"/>
    </inertial>
  </link>
  <link name="right_link_3">
    <visual>
      <origin rpy="0 0 0" xyz="0 0 0"/>
      <geometry>
        <mesh filename="package://asystr_sensible_model/meshes/visual/asystr_sensible/link_3.dae" scale="0.001 0.001 -0.001"/>
      </geometry>
    </visual>
    <collision>
      <origin rpy="0 0 0" xyz="0 0 0"/>
      <geometry>
        <mesh filename="package://asystr_sensible_model/meshes/collision/asystr_sensible/link_3.stl" scale="0.001 0.001 -0.001"/>
      </geometry>
    </collision>
    <inertial>
      <origin rpy="0 0 0" xyz="0 0 0"/>
      <mass value="0.01"/>
      <inertia ixx="0.01" ixy="0.0" ixz="0.0" iyy="0.01" iyz="0.0" izz="0.01"/>
    </inertial>
  </link>
  <link name="right_wrist_adapter">
    <visual>
      <origin rpy="0 0 0" xyz="0 0 0"/>
      <geometry>
        <mesh filename="package://asystr_sensible_model/meshes/visual/RPR/wrist_adapter.dae" scale="0.001 0.001 0.001"/>
      </geometry>
    </visual>
    <collision>
      <origin rpy="0 0 0" xyz="0 0 0"/>
      <geometry>
        <mesh filename="package://asystr_sensible_model/meshes/collision/RPR/wrist_adapter.stl" scale="0.001 0.001 0.001"/>
      </geometry>
    </collision>
    <inertial>
      <origin rpy="0 0 0" xyz="0 0 0"/>
      <mass value="0.01"/>
      <inertia ixx="0.01" ixy="0.0" ixz="0.0" iyy="0.01" iyz="0.0" izz="0.01"/>
    </inertial>
  </link>
  <!-- Create Joints -->
  <joint name="right_joint_1" type="revolute">
    <parent link="right_base_link"/>
    <child link="right_link_1"/>
    <origin rpy="0 0.0 0.0" xyz="0 -0.0 0.2592"/>
    <axis xyz="0 0 1"/>
    <limit effort="100.0" lower="-3.141592653589793" upper="3.141592653589793" velocity="100.0"/>
  </joint>
  <joint name="right_joint_2" type="revolute">
    <parent link="right_link_1"/>
    <child link="right_link_2"/>
    <origin rpy="1.5707963 -1.5707962999999996 4.2089324414645615e-08" xyz="0 0.0 0.0"/>
    <axis xyz="0 0 1"/>
    <limit effort="100.0" lower="-2.0943951023931953" upper="1.5707963267948966" velocity="100.0"/>
  </joint>
  <joint name="right_joint_3" type="revolute">
    <parent link="right_link_2"/>
    <child link="right_link_3"/>
    <origin rpy="0 0.0 -1.5707963" xyz="0.45 0.0 0.0"/>
    <axis xyz="0 0 1"/>
    <limit effort="100.0" lower="0.0" upper="3.141592653589793" velocity="100.0"/>
  </joint>
  <joint name="right_wrist_frame" type="fixed">
    <parent link="right_link_3"/>
    <child link="right_wrist_adapter"/>
    <origin rpy="1.5707963 1.5707962999999996 -4.2089324414645615e-08" xyz="0.117 -0.3299999999999999 8.84231587305945e-09"/>
  </joint>
  <!-- Create Links -->
  <link name="right_link_4">
    <visual>
      <origin rpy="0 0 0" xyz="0 0 0"/>
      <geometry>
        <mesh filename="package://asystr_sensible_model/meshes/visual/RPR/differential.dae" scale="0.001 0.001 0.001"/>
      </geometry>
    </visual>
    <collision>
      <origin rpy="0 0 0" xyz="0 0 0"/>
      <geometry>
        <mesh filename="package://asystr_sensible_model/meshes/collision/RPR/differential.stl" scale="0.001 0.001 0.001"/>
      </geometry>
    </collision>
    <inertial>
      <origin rpy="0 0 0" xyz="0 0 0"/>
      <mass value="0.01"/>
      <inertia ixx="0.01" ixy="0.0" ixz="0.0" iyy="0.01" iyz="0.0" izz="0.01"/>
    </inertial>
  </link>
  <link name="right_link_5">
    <inertial>
      <origin rpy="0 0 0" xyz="0 0 0"/>
      <mass value="0.01"/>
      <inertia ixx="0.01" ixy="0.0" ixz="0.0" iyy="0.01" iyz="0.0" izz="0.01"/>
    </inertial>
  </link>
  <link name="right_link_6">
    <visual>
      <origin rpy="0 0 0" xyz="0 0 0"/>
      <geometry>
        <mesh filename="package://asystr_sensible_model/meshes/visual/RPR/flange.dae" scale="0.001 0.001 0.001"/>
      </geometry>
    </visual>
    <collision>
      <origin rpy="0 0 0" xyz="0 0 0"/>
      <geometry>
        <mesh filename="package://asystr_sensible_model/meshes/collision/RPR/flange.stl" scale="0.001 0.001 0.001"/>
      </geometry>
    </collision>
    <inertial>
      <origin rpy="0 0 0" xyz="0 0 0"/>
      <mass value="0.01"/>
      <inertia ixx="0.01" ixy="0.0" ixz="0.0" iyy="0.01" iyz="0.0" izz="0.01"/>
    </inertial>
  </link>
  <!-- Create Joints -->
  <joint name="right_joint_4" type="revolute">
    <parent link="right_wrist_adapter"/>
    <child link="right_link_4"/>
    <origin rpy="0 -0.0 1.5707963" xyz="0 -0.0 0.08"/>
    <axis xyz="0 0 1"/>
    <limit effort="100.0" lower="-3.141592653589793" upper="3.141592653589793" velocity="100.0"/>
  </joint>
  <joint name="right_joint_5" type="revolute">
    <parent link="right_link_4"/>
    <child link="right_link_5"/>
    <origin rpy="1.5707963 0.0 0.0" xyz="0 0.0 0.0"/>
    <axis xyz="0 0 1"/>
    <limit effort="100.0" lower="-1.5707963267948966" upper="1.5707963267948966" velocity="100.0"/>
  </joint>
  <joint name="right_joint_6" type="revolute">
    <parent link="right_link_5"/>
    <child link="right_link_6"/>
    <origin rpy="-1.5707963 -0.0 0.0" xyz="0 0.04999999999999999 1.3397448292514317e-09"/>
    <axis xyz="0 0 1"/>
    <limit effort="100.0" lower="-3.141592653589793" upper="3.141592653589793" velocity="100.0"/>
  </joint>
  <joint name="base_to_right" type="fixed">
    <parent link="base_link"/>
    <child link="right_base_link"/>
    <origin rpy="3.141592653589793 0 0" xyz="0.76 -0.28 1.475"/>
  </joint>
</robot>
