<?xml version="1.0" ?>
<!-- =================================================================================== -->
<!-- |    This document was autogenerated by xacro from sherpa_dual_arm.urdf.xacro     | -->
<!-- |    EDITING THIS FILE BY HAND IS NOT RECOMMENDED                                 | -->
<!-- =================================================================================== -->
<robot name="sherpa_dual_arm">
  <link name="base_link"/>
  <joint name="footprint_joint" type="fixed">
    <parent link="base_link"/>
    <child link="base_footprint"/>
    <origin rpy="0 0 0" xyz="0 0 0.026"/>
  </joint>
  <!-- Sherpa Chasis -->
  <link name="base_footprint">
    <inertial>
      <origin rpy="0 0 0" xyz="0 0 0"/>
      <mass value="0.01"/>
      <inertia ixx="0.01" ixy="0.0" ixz="0.0" iyy="0.01" iyz="0.0" izz="0.01"/>
    </inertial>
    <visual>
      <origin rpy="0 0 0" xyz="0 0 0"/>
      <geometry>
        <mesh filename="package://asystr_dual_arm_model/meshes/visual/sherpa_chassis.dae" scale="0.1 0.1 0.1"/>
      </geometry>
    </visual>
    <collision>
      <origin rpy="0 0 0" xyz="0 0 0"/>
      <geometry>
        <mesh filename="package://asystr_dual_arm_model/meshes/collision/sherpa_chassis.stl" scale="0.1 0.1 0.1"/>
      </geometry>
    </collision>
  </link>
  <!-- Front Left Wheel -->
  <link name="front_left_wheel_base">
    <inertial>
      <origin rpy="0 0 0" xyz="0 0 0"/>
      <mass value="0.01"/>
      <inertia ixx="0.01" ixy="0.0" ixz="0.0" iyy="0.01" iyz="0.0" izz="0.01"/>
    </inertial>
    <visual>
      <origin rpy="0 1.5707963267948966 0" xyz="0 0 0"/>
      <geometry>
        <mesh filename="package://asystr_dual_arm_model/meshes/visual/sherpa_wheel_base.dae" scale="0.1 0.1 0.1"/>
      </geometry>
    </visual>
    <collision>
      <origin rpy="0 1.5707963267948966 0" xyz="0 0 0"/>
      <geometry>
        <mesh filename="package://asystr_dual_arm_model/meshes/collision/sherpa_wheel_base.stl" scale="0.1 0.1 0.1"/>
      </geometry>
    </collision>
  </link>
  <joint name="front_left_wheel_base_joint" type="continuous">
    <parent link="base_link"/>
    <child link="front_left_wheel_base"/>
    <origin rpy="0 -1.5707963267948966 0" xyz="0.23985 0.213 0.16"/>
    <axis xyz="1 0 0"/>
  </joint>
  <link name="front_left_wheel">
    <inertial>
      <origin rpy="0 0 0" xyz="0 0 0"/>
      <mass value="0.01"/>
      <inertia ixx="0.01" ixy="0.0" ixz="0.0" iyy="0.01" iyz="0.0" izz="0.01"/>
    </inertial>
    <visual>
      <origin rpy="0 1.5707963267948966 0" xyz="0 0 0"/>
      <geometry>
        <mesh filename="package://asystr_dual_arm_model/meshes/visual/sherpa_wheel.dae" scale="0.1 0.1 0.1"/>
      </geometry>
    </visual>
    <collision>
      <origin rpy="0 1.5707963267948966 0" xyz="0 0 0"/>
      <geometry>
        <mesh filename="package://asystr_dual_arm_model/meshes/collision/sherpa_wheel.stl" scale="0.1 0.1 0.1"/>
      </geometry>
    </collision>
  </link>
  <joint name="front_left_wheel_joint" type="continuous">
    <parent link="front_left_wheel_base"/>
    <child link="front_left_wheel"/>
    <origin rpy="0 0 -1.5707963267948966" xyz="-0.11 0 0"/>
    <axis xyz="1 0 0"/>
  </joint>
  <!-- Front Right Wheel -->
  <link name="front_right_wheel_base">
    <inertial>
      <origin rpy="0 0 0" xyz="0 0 0"/>
      <mass value="0.01"/>
      <inertia ixx="0.01" ixy="0.0" ixz="0.0" iyy="0.01" iyz="0.0" izz="0.01"/>
    </inertial>
    <visual>
      <origin rpy="3.141592653589793 1.5707963267948966 0" xyz="0 0 0"/>
      <geometry>
        <mesh filename="package://asystr_dual_arm_model/meshes/visual/sherpa_wheel_base.dae" scale="0.1 0.1 0.1"/>
      </geometry>
    </visual>
    <collision>
      <origin rpy="3.141592653589793 1.5707963267948966 0" xyz="0 0 0"/>
      <geometry>
        <mesh filename="package://asystr_dual_arm_model/meshes/collision/sherpa_wheel_base.stl" scale="0.1 0.1 0.1"/>
      </geometry>
    </collision>
  </link>
  <joint name="front_right_wheel_base_joint" type="continuous">
    <parent link="base_link"/>
    <child link="front_right_wheel_base"/>
    <origin rpy="0 1.5707963267948966 0" xyz="0.23985 -0.213 0.16"/>
    <axis xyz="1 0 0"/>
  </joint>
  <link name="front_right_wheel">
    <inertial>
      <origin rpy="0 0 0" xyz="0 0 0"/>
      <mass value="0.01"/>
      <inertia ixx="0.01" ixy="0.0" ixz="0.0" iyy="0.01" iyz="0.0" izz="0.01"/>
    </inertial>
    <visual>
      <origin rpy="0 1.5707963267948966 0" xyz="0 0 0"/>
      <geometry>
        <mesh filename="package://asystr_dual_arm_model/meshes/visual/sherpa_wheel.dae" scale="0.1 0.1 0.1"/>
      </geometry>
    </visual>
    <collision>
      <origin rpy="0 1.5707963267948966 0" xyz="0 0 0"/>
      <geometry>
        <mesh filename="package://asystr_dual_arm_model/meshes/collision/sherpa_wheel.stl" scale="0.1 0.1 0.1"/>
      </geometry>
    </collision>
  </link>
  <joint name="front_right_wheel_joint" type="continuous">
    <parent link="front_right_wheel_base"/>
    <child link="front_right_wheel"/>
    <origin rpy="0 0 1.5707963267948966" xyz="0.11 0 0"/>
    <axis xyz="1 0 0"/>
  </joint>
  <!-- Rear Left Wheel -->
  <link name="rear_left_wheel_base">
    <inertial>
      <origin rpy="0 0 0" xyz="0 0 0"/>
      <mass value="0.01"/>
      <inertia ixx="0.01" ixy="0.0" ixz="0.0" iyy="0.01" iyz="0.0" izz="0.01"/>
    </inertial>
    <visual>
      <origin rpy="0 -1.5707963267948966 0" xyz="0 0 0"/>
      <geometry>
        <mesh filename="package://asystr_dual_arm_model/meshes/visual/sherpa_wheel_base.dae" scale="0.1 0.1 0.1"/>
      </geometry>
    </visual>
    <collision>
      <origin rpy="0 -1.5707963267948966 0" xyz="0 0 0"/>
      <geometry>
        <mesh filename="package://asystr_dual_arm_model/meshes/collision/sherpa_wheel_base.stl" scale="0.1 0.1 0.1"/>
      </geometry>
    </collision>
  </link>
  <joint name="rear_left_wheel_base_joint" type="continuous">
    <parent link="base_link"/>
    <child link="rear_left_wheel_base"/>
    <origin rpy="0 1.5707963267948966 0" xyz="-0.23985 0.213 0.16"/>
    <axis xyz="1 0 0"/>
  </joint>
  <link name="rear_left_wheel">
    <inertial>
      <origin rpy="0 0 0" xyz="0 0 0"/>
      <mass value="0.01"/>
      <inertia ixx="0.01" ixy="0.0" ixz="0.0" iyy="0.01" iyz="0.0" izz="0.01"/>
    </inertial>
    <visual>
      <origin rpy="0 -1.5707963267948966 0" xyz="0 0 0"/>
      <geometry>
        <mesh filename="package://asystr_dual_arm_model/meshes/visual/sherpa_wheel.dae" scale="0.1 0.1 0.1"/>
      </geometry>
    </visual>
    <collision>
      <origin rpy="0 1.5707963267948966 0" xyz="0 0 0"/>
      <geometry>
        <mesh filename="package://asystr_dual_arm_model/meshes/collision/sherpa_wheel.stl" scale="0.1 0.1 0.1"/>
      </geometry>
    </collision>
  </link>
  <joint name="rear_left_wheel_joint" type="continuous">
    <parent link="rear_left_wheel_base"/>
    <child link="rear_left_wheel"/>
    <origin rpy="0 0 1.5707963267948966" xyz="0.11 0 0"/>
    <axis xyz="1 0 0"/>
  </joint>
  <!-- Rear Right Wheel -->
  <link name="rear_right_wheel_base">
    <inertial>
      <origin rpy="0 0 0" xyz="0 0 0"/>
      <mass value="0.01"/>
      <inertia ixx="0.01" ixy="0.0" ixz="0.0" iyy="0.01" iyz="0.0" izz="0.01"/>
    </inertial>
    <visual>
      <origin rpy="3.141592653589793 -1.5707963267948966 0" xyz="0 0 0"/>
      <geometry>
        <mesh filename="package://asystr_dual_arm_model/meshes/visual/sherpa_wheel_base.dae" scale="0.1 0.1 0.1"/>
      </geometry>
    </visual>
    <collision>
      <origin rpy="3.141592653589793 -1.5707963267948966 0" xyz="0 0 0"/>
      <geometry>
        <mesh filename="package://asystr_dual_arm_model/meshes/collision/sherpa_wheel_base.stl" scale="0.1 0.1 0.1"/>
      </geometry>
    </collision>
  </link>
  <joint name="rear_right_wheel_base_joint" type="continuous">
    <parent link="base_link"/>
    <child link="rear_right_wheel_base"/>
    <origin rpy="0 -1.5707963267948966 0" xyz="-0.23985 -0.213 0.16"/>
    <axis xyz="1 0 0"/>
  </joint>
  <link name="rear_right_wheel">
    <inertial>
      <origin rpy="0 0 0" xyz="0 0 0"/>
      <mass value="0.01"/>
      <inertia ixx="0.01" ixy="0.0" ixz="0.0" iyy="0.01" iyz="0.0" izz="0.01"/>
    </inertial>
    <visual>
      <origin rpy="0 1.5707963267948966 0" xyz="0 0 0"/>
      <geometry>
        <mesh filename="package://asystr_dual_arm_model/meshes/visual/sherpa_wheel.dae" scale="0.1 0.1 0.1"/>
      </geometry>
    </visual>
    <collision>
      <origin rpy="0 1.5707963267948966 0" xyz="0 0 0"/>
      <geometry>
        <mesh filename="package://asystr_dual_arm_model/meshes/collision/sherpa_wheel.stl" scale="0.1 0.1 0.1"/>
      </geometry>
    </collision>
  </link>
  <joint name="rear_right_wheel_joint" type="continuous">
    <parent link="rear_right_wheel_base"/>
    <child link="rear_right_wheel"/>
    <origin rpy="0 0 1.5707963267948966" xyz="-0.11 0 0"/>
    <axis xyz="1 0 0"/>
  </joint>
  <link name="telescopic_base">
    <inertial>
      <origin rpy="0 0 0" xyz="0 0 0"/>
      <mass value="0.01"/>
      <inertia ixx="0.01" ixy="0.0" ixz="0.0" iyy="0.01" iyz="0.0" izz="0.01"/>
    </inertial>
    <visual>
      <origin rpy="0 0 0" xyz="0 0 0"/>
      <geometry>
        <mesh filename="package://asystr_dual_arm_model/meshes/visual/sherpa_tele_base.dae" scale="0.01 0.01 0.01"/>
      </geometry>
    </visual>
    <collision>
      <origin rpy="0 0 0" xyz="0 0 0"/>
      <geometry>
        <mesh filename="package://asystr_dual_arm_model/meshes/collision/sherpa_tele_base.stl" scale="0.01 0.01 0.01"/>
      </geometry>
    </collision>
  </link>
  <joint name="telescopic_base_joint" type="fixed">
    <parent link="base_link"/>
    <child link="telescopic_base"/>
    <origin rpy="0 0 0" xyz="0 0 0.253"/>
    <axis xyz="1 0 0"/>
  </joint>
  <link name="telescopic_mid">
    <inertial>
      <origin rpy="0 0 0" xyz="0 0 0"/>
      <mass value="0.01"/>
      <inertia ixx="0.01" ixy="0.0" ixz="0.0" iyy="0.01" iyz="0.0" izz="0.01"/>
    </inertial>
    <visual>
      <origin rpy="0 0 0" xyz="0 0 0"/>
      <geometry>
        <mesh filename="package://asystr_dual_arm_model/meshes/visual/sherpa_tele_mid.dae" scale="0.01 0.01 0.01"/>
      </geometry>
    </visual>
    <collision>
      <origin rpy="0 0 0" xyz="0 0 0"/>
      <geometry>
        <mesh filename="package://asystr_dual_arm_model/meshes/collision/sherpa_tele_mid.stl" scale="0.01 0.01 0.01"/>
      </geometry>
    </collision>
  </link>
  <joint name="telescopic_mid_joint" type="prismatic">
    <parent link="telescopic_base"/>
    <child link="telescopic_mid"/>
    <origin rpy="0 0 0" xyz="0 0 0.077"/>
    <axis xyz="0 0 1"/>
    <limit effort="100.0" lower="-0.02" upper="0.47" velocity="0.1"/>
  </joint>
  <link name="sherpa_body">
    <inertial>
      <origin rpy="0 0 0" xyz="0 0 0"/>
      <mass value="0.01"/>
      <inertia ixx="0.01" ixy="0.0" ixz="0.0" iyy="0.01" iyz="0.0" izz="0.01"/>
    </inertial>
    <visual>
      <origin rpy="0 0 0" xyz="0 0 0"/>
      <geometry>
        <mesh filename="package://asystr_dual_arm_model/meshes/visual/sherpa_tele_body.dae" scale="0.01 0.01 0.01"/>
      </geometry>
    </visual>
    <collision>
      <origin rpy="0 0 0" xyz="0 0 0"/>
      <geometry>
        <mesh filename="package://asystr_dual_arm_model/meshes/collision/sherpa_tele_body.stl" scale="0.01 0.01 0.01"/>
      </geometry>
    </collision>
  </link>
  <joint name="sherpa_body_joint" type="prismatic">
    <parent link="telescopic_mid"/>
    <child link="sherpa_body"/>
    <origin rpy="0 0 0" xyz="0 0 0.04"/>
    <axis xyz="0 0 1"/>
    <limit effort="100.0" lower="-0.02" upper="0.47" velocity="0.1"/>
  </joint>
  <link name="sherpa_head_yaw"/>
  <joint name="sherpa_body_yaw_joint" type="revolute">
    <parent link="sherpa_body"/>
    <child link="sherpa_head_yaw"/>
    <origin rpy="0 0 0" xyz="0 0 0.76"/>
    <axis xyz="0 0 1"/>
    <limit effort="100.0" lower="-0.7853981633974483" upper="0.7853981633974483" velocity="0.1"/>
  </joint>
  <link name="sherpa_head">
    <inertial>
      <origin rpy="0 0 0" xyz="0 0 0"/>
      <mass value="0.01"/>
      <inertia ixx="0.01" ixy="0.0" ixz="0.0" iyy="0.01" iyz="0.0" izz="0.01"/>
    </inertial>
    <visual>
      <origin rpy="0 0 0" xyz="0 0 0"/>
      <geometry>
        <mesh filename="package://asystr_dual_arm_model/meshes/visual/sherpa_head.dae" scale="0.01 0.01 0.01"/>
      </geometry>
    </visual>
    <collision>
      <origin rpy="0 0 0" xyz="0 0 0"/>
      <geometry>
        <mesh filename="package://asystr_dual_arm_model/meshes/collision/sherpa_head.stl" scale="0.01 0.01 0.01"/>
      </geometry>
    </collision>
  </link>
  <joint name="sherpa_body_tilt_joint" type="revolute">
    <parent link="sherpa_head_yaw"/>
    <child link="sherpa_head"/>
    <origin rpy="0 0 0" xyz="0 0 0"/>
    <axis xyz="0 1 0"/>
    <limit effort="100.0" lower="-0.5235987755982988" upper="0.5235987755982988" velocity="0.1"/>
  </joint>
  <!-- Import dependency files -->
  <!-- Import dependency files -->
  <!-- Create Links -->
  <link name="left_base_link">
    <visual>
      <origin rpy="0 0 0" xyz="0 0 0"/>
      <geometry>
        <mesh filename="package://asystr_sensible_model/meshes/visual/asystr_sensible/base_link.dae" scale="0.001 0.001 0.001"/>
      </geometry>
    </visual>
    <collision>
      <origin rpy="0 0 0" xyz="0 0 0"/>
      <geometry>
        <mesh filename="package://asystr_sensible_model/meshes/collision/asystr_sensible/base_link.stl" scale="0.001 0.001 0.001"/>
      </geometry>
    </collision>
    <inertial>
      <origin rpy="0 0 0" xyz="0 0 0"/>
      <mass value="0.01"/>
      <inertia ixx="0.01" ixy="0.0" ixz="0.0" iyy="0.01" iyz="0.0" izz="0.01"/>
    </inertial>
  </link>
  <link name="left_link_1">
    <visual>
      <origin rpy="0 0 0" xyz="0 0 0"/>
      <geometry>
        <mesh filename="package://asystr_sensible_model/meshes/visual/asystr_sensible/link_1.dae" scale="0.001 0.001 0.001"/>
      </geometry>
    </visual>
    <collision>
      <origin rpy="0 0 0" xyz="0 0 0"/>
      <geometry>
        <mesh filename="package://asystr_sensible_model/meshes/collision/asystr_sensible/link_1.stl" scale="0.001 0.001 0.001"/>
      </geometry>
    </collision>
    <inertial>
      <origin rpy="0 0 0" xyz="0 0 0"/>
      <mass value="0.01"/>
      <inertia ixx="0.01" ixy="0.0" ixz="0.0" iyy="0.01" iyz="0.0" izz="0.01"/>
    </inertial>
  </link>
  <link name="left_link_2">
    <visual>
      <origin rpy="0 0 0" xyz="0 0 0"/>
      <geometry>
        <mesh filename="package://asystr_sensible_model/meshes/visual/asystr_sensible/link_2.dae" scale="0.001 0.001 0.001"/>
      </geometry>
    </visual>
    <collision>
      <origin rpy="0 0 0" xyz="0 0 0"/>
      <geometry>
        <mesh filename="package://asystr_sensible_model/meshes/collision/asystr_sensible/link_2.stl" scale="0.001 0.001 0.001"/>
      </geometry>
    </collision>
    <inertial>
      <origin rpy="0 0 0" xyz="0 0 0"/>
      <mass value="0.01"/>
      <inertia ixx="0.01" ixy="0.0" ixz="0.0" iyy="0.01" iyz="0.0" izz="0.01"/>
    </inertial>
  </link>
  <link name="left_link_3">
    <visual>
      <origin rpy="0 0 0" xyz="0 0 0"/>
      <geometry>
        <mesh filename="package://asystr_sensible_model/meshes/visual/asystr_sensible/link_3.dae" scale="0.001 0.001 0.001"/>
      </geometry>
    </visual>
    <collision>
      <origin rpy="0 0 0" xyz="0 0 0"/>
      <geometry>
        <mesh filename="package://asystr_sensible_model/meshes/collision/asystr_sensible/link_3.stl" scale="0.001 0.001 0.001"/>
      </geometry>
    </collision>
    <inertial>
      <origin rpy="0 0 0" xyz="0 0 0"/>
      <mass value="0.01"/>
      <inertia ixx="0.01" ixy="0.0" ixz="0.0" iyy="0.01" iyz="0.0" izz="0.01"/>
    </inertial>
  </link>
  <link name="left_wrist_adapter">
    <visual>
      <origin rpy="0 0 0" xyz="0 0 0"/>
      <geometry>
        <mesh filename="package://asystr_sensible_model/meshes/visual/RPR/wrist_adapter.dae" scale="0.001 0.001 0.001"/>
      </geometry>
    </visual>
    <collision>
      <origin rpy="0 0 0" xyz="0 0 0"/>
      <geometry>
        <mesh filename="package://asystr_sensible_model/meshes/collision/RPR/wrist_adapter.stl" scale="0.001 0.001 0.001"/>
      </geometry>
    </collision>
    <inertial>
      <origin rpy="0 0 0" xyz="0 0 0"/>
      <mass value="0.01"/>
      <inertia ixx="0.01" ixy="0.0" ixz="0.0" iyy="0.01" iyz="0.0" izz="0.01"/>
    </inertial>
  </link>
  <!-- Create Joints -->
  <joint name="left_joint_1" type="continuous">
    <parent link="left_base_link"/>
    <child link="left_link_1"/>
    <origin rpy="0 0.0 0.0" xyz="0 -0.0 0.2592"/>
    <axis xyz="0 0 1"/>
    <limit effort="100.0" lower="-3.141592653589793" upper="3.141592653589793" velocity="100.0"/>
  </joint>
  <joint name="left_joint_2" type="revolute">
    <parent link="left_link_1"/>
    <child link="left_link_2"/>
    <origin rpy="1.5707963 -3.141579999999999 8.417831121359425e-08" xyz="0 0.0 0.0"/>
    <axis xyz="0 0 1"/>
    <limit effort="100.0" lower="-3.665191429188092" upper="0.0" velocity="100.0"/>
  </joint>
  <joint name="left_joint_3" type="revolute">
    <parent link="left_link_2"/>
    <child link="left_link_3"/>
    <origin rpy="0 0.0 -1.5707963" xyz="0.45 0.0 0.0"/>
    <axis xyz="0 0 1"/>
    <limit effort="100.0" lower="0.0" upper="3.141592653589793" velocity="100.0"/>
  </joint>
  <joint name="left_wrist_frame" type="fixed">
    <parent link="left_link_3"/>
    <child link="left_wrist_adapter"/>
    <origin rpy="1.5707963 1.5707962999999996 -4.2089324414645615e-08" xyz="0.12 -0.3299999999999999 8.84231587305945e-09"/>
  </joint>
  <!-- Create Links -->
  <link name="left_link_4">
    <visual>
      <origin rpy="0 0 0" xyz="0 0 0"/>
      <geometry>
        <mesh filename="package://asystr_sensible_model/meshes/visual/RPR/wrist_roll.dae" scale="0.001 0.001 0.001"/>
      </geometry>
    </visual>
    <collision>
      <origin rpy="0 0 0" xyz="0 0 0"/>
      <geometry>
        <mesh filename="package://asystr_sensible_model/meshes/collision/RPR/wrist_roll.stl" scale="0.001 0.001 0.001"/>
      </geometry>
    </collision>
    <inertial>
      <origin rpy="0 0 0" xyz="0 0 0"/>
      <mass value="0.01"/>
      <inertia ixx="0.01" ixy="0.0" ixz="0.0" iyy="0.01" iyz="0.0" izz="0.01"/>
    </inertial>
  </link>
  <link name="left_link_5">
    <visual>
      <origin rpy="0 0 0" xyz="0 0 0"/>
      <geometry>
        <mesh filename="package://asystr_sensible_model/meshes/visual/RPR/differential.dae" scale="0.001 0.001 0.001"/>
      </geometry>
    </visual>
    <collision>
      <origin rpy="0 0 0" xyz="0 0 0"/>
      <geometry>
        <mesh filename="package://asystr_sensible_model/meshes/collision/RPR/differential.stl" scale="0.001 0.001 0.001"/>
      </geometry>
    </collision>
    <inertial>
      <origin rpy="0 0 0" xyz="0 0 0"/>
      <mass value="0.01"/>
      <inertia ixx="0.01" ixy="0.0" ixz="0.0" iyy="0.01" iyz="0.0" izz="0.01"/>
    </inertial>
  </link>
  <link name="left_link_6">
    <visual>
      <origin rpy="0 0 0" xyz="0 0 0"/>
      <geometry>
        <mesh filename="package://asystr_sensible_model/meshes/visual/RPR/flange.dae" scale="0.001 -0.001 0.001"/>
      </geometry>
    </visual>
    <collision>
      <origin rpy="0 0 0" xyz="0 0 0"/>
      <geometry>
        <mesh filename="package://asystr_sensible_model/meshes/collision/RPR/flange.stl" scale="0.001 -0.001 0.001"/>
      </geometry>
    </collision>
    <inertial>
      <origin rpy="0 0 0" xyz="0 0 0"/>
      <mass value="0.01"/>
      <inertia ixx="0.01" ixy="0.0" ixz="0.0" iyy="0.01" iyz="0.0" izz="0.01"/>
    </inertial>
  </link>
  <!-- Create Joints -->
  <joint name="left_joint_4" type="continuous">
    <parent link="left_wrist_adapter"/>
    <child link="left_link_4"/>
    <origin rpy="0 -0.0 1.5707963" xyz="0 -0.0 0.088"/>
    <axis xyz="0 0 1"/>
    <limit effort="100.0" lower="-3.141592653589793" upper="3.141592653589793" velocity="100.0"/>
  </joint>
  <joint name="left_joint_5" type="revolute">
    <parent link="left_link_4"/>
    <child link="left_link_5"/>
    <origin rpy="1.5707963 0.0 0.0" xyz="0 0.0 0.0"/>
    <axis xyz="0 0 1"/>
    <limit effort="100.0" lower="-2.0943951023931953" upper="2.0943951023931953" velocity="100.0"/>
  </joint>
  <joint name="left_joint_6" type="continuous">
    <parent link="left_link_5"/>
    <child link="left_link_6"/>
    <origin rpy="-1.5707963 -0.0 0.0" xyz="0 0.06949999999999998 1.8622453126594902e-09"/>
    <axis xyz="0 0 1"/>
    <limit effort="100.0" lower="-3.141592653589793" upper="3.141592653589793" velocity="100.0"/>
  </joint>
  <joint name="sherpa_body_to_left" type="fixed">
    <parent link="sherpa_body"/>
    <child link="left_base_link"/>
    <origin rpy="3.141592653589793 0 0" xyz="0.0 0.28 0.575"/>
  </joint>
  <!-- Import dependency files -->
  <!-- Import dependency files -->
  <!-- Create Links -->
  <link name="right_base_link">
    <visual>
      <origin rpy="0 0 0" xyz="0 0 0"/>
      <geometry>
        <mesh filename="package://asystr_sensible_model/meshes/visual/asystr_sensible/base_link.dae" scale="0.001 -0.001 0.001"/>
      </geometry>
    </visual>
    <collision>
      <origin rpy="0 0 0" xyz="0 0 0"/>
      <geometry>
        <mesh filename="package://asystr_sensible_model/meshes/collision/asystr_sensible/base_link.stl" scale="0.001 -0.001 0.001"/>
      </geometry>
    </collision>
    <inertial>
      <origin rpy="0 0 0" xyz="0 0 0"/>
      <mass value="0.01"/>
      <inertia ixx="0.01" ixy="0.0" ixz="0.0" iyy="0.01" iyz="0.0" izz="0.01"/>
    </inertial>
  </link>
  <link name="right_link_1">
    <visual>
      <origin rpy="0 0 0" xyz="0 0 0"/>
      <geometry>
        <mesh filename="package://asystr_sensible_model/meshes/visual/asystr_sensible/link_1.dae" scale="0.001 -0.001 0.001"/>
      </geometry>
    </visual>
    <collision>
      <origin rpy="0 0 0" xyz="0 0 0"/>
      <geometry>
        <mesh filename="package://asystr_sensible_model/meshes/collision/asystr_sensible/link_1.stl" scale="0.001 -0.001 0.001"/>
      </geometry>
    </collision>
    <inertial>
      <origin rpy="0 0 0" xyz="0 0 0"/>
      <mass value="0.01"/>
      <inertia ixx="0.01" ixy="0.0" ixz="0.0" iyy="0.01" iyz="0.0" izz="0.01"/>
    </inertial>
  </link>
  <link name="right_link_2">
    <visual>
      <origin rpy="0 0 0" xyz="0 0 0"/>
      <geometry>
        <mesh filename="package://asystr_sensible_model/meshes/visual/asystr_sensible/link_2.dae" scale="0.001 0.001 -0.001"/>
      </geometry>
    </visual>
    <collision>
      <origin rpy="0 0 0" xyz="0 0 0"/>
      <geometry>
        <mesh filename="package://asystr_sensible_model/meshes/collision/asystr_sensible/link_2.stl" scale="0.001 0.001 -0.001"/>
      </geometry>
    </collision>
    <inertial>
      <origin rpy="0 0 0" xyz="0 0 0"/>
      <mass value="0.01"/>
      <inertia ixx="0.01" ixy="0.0" ixz="0.0" iyy="0.01" iyz="0.0" izz="0.01"/>
    </inertial>
  </link>
  <link name="right_link_3">
    <visual>
      <origin rpy="0 0 0" xyz="0 0 0"/>
      <geometry>
        <mesh filename="package://asystr_sensible_model/meshes/visual/asystr_sensible/link_3.dae" scale="0.001 0.001 -0.001"/>
      </geometry>
    </visual>
    <collision>
      <origin rpy="0 0 0" xyz="0 0 0"/>
      <geometry>
        <mesh filename="package://asystr_sensible_model/meshes/collision/asystr_sensible/link_3.stl" scale="0.001 0.001 -0.001"/>
      </geometry>
    </collision>
    <inertial>
      <origin rpy="0 0 0" xyz="0 0 0"/>
      <mass value="0.01"/>
      <inertia ixx="0.01" ixy="0.0" ixz="0.0" iyy="0.01" iyz="0.0" izz="0.01"/>
    </inertial>
  </link>
  <link name="right_wrist_adapter">
    <visual>
      <origin rpy="0 0 0" xyz="0 0 0"/>
      <geometry>
        <mesh filename="package://asystr_sensible_model/meshes/visual/RPR/wrist_adapter.dae" scale="0.001 0.001 0.001"/>
      </geometry>
    </visual>
    <collision>
      <origin rpy="0 0 0" xyz="0 0 0"/>
      <geometry>
        <mesh filename="package://asystr_sensible_model/meshes/collision/RPR/wrist_adapter.stl" scale="0.001 0.001 0.001"/>
      </geometry>
    </collision>
    <inertial>
      <origin rpy="0 0 0" xyz="0 0 0"/>
      <mass value="0.01"/>
      <inertia ixx="0.01" ixy="0.0" ixz="0.0" iyy="0.01" iyz="0.0" izz="0.01"/>
    </inertial>
  </link>
  <!-- Create Joints -->
  <joint name="right_joint_1" type="continuous">
    <parent link="right_base_link"/>
    <child link="right_link_1"/>
    <origin rpy="0 0.0 0.0" xyz="0 -0.0 0.2592"/>
    <axis xyz="0 0 1"/>
    <limit effort="100.0" lower="-3.141592653589793" upper="3.141592653589793" velocity="100.0"/>
  </joint>
  <joint name="right_joint_2" type="revolute">
    <parent link="right_link_1"/>
    <child link="right_link_2"/>
    <origin rpy="1.5707963 -3.141579999999999 8.417831121359425e-08" xyz="0 0.0 0.0"/>
    <axis xyz="0 0 1"/>
    <limit effort="100.0" lower="-3.665191429188092" upper="0.0" velocity="100.0"/>
  </joint>
  <joint name="right_joint_3" type="revolute">
    <parent link="right_link_2"/>
    <child link="right_link_3"/>
    <origin rpy="0 0.0 -1.5707963" xyz="0.45 0.0 0.0"/>
    <axis xyz="0 0 1"/>
    <limit effort="100.0" lower="0.0" upper="3.141592653589793" velocity="100.0"/>
  </joint>
  <joint name="right_wrist_frame" type="fixed">
    <parent link="right_link_3"/>
    <child link="right_wrist_adapter"/>
    <origin rpy="1.5707963 1.5707962999999996 -4.2089324414645615e-08" xyz="0.12 -0.3299999999999999 8.84231587305945e-09"/>
  </joint>
  <!-- Create Links -->
  <link name="right_link_4">
    <visual>
      <origin rpy="0 0 0" xyz="0 0 0"/>
      <geometry>
        <mesh filename="package://asystr_sensible_model/meshes/visual/RPR/wrist_roll.dae" scale="0.001 0.001 0.001"/>
      </geometry>
    </visual>
    <collision>
      <origin rpy="0 0 0" xyz="0 0 0"/>
      <geometry>
        <mesh filename="package://asystr_sensible_model/meshes/collision/RPR/wrist_roll.stl" scale="0.001 0.001 0.001"/>
      </geometry>
    </collision>
    <inertial>
      <origin rpy="0 0 0" xyz="0 0 0"/>
      <mass value="0.01"/>
      <inertia ixx="0.01" ixy="0.0" ixz="0.0" iyy="0.01" iyz="0.0" izz="0.01"/>
    </inertial>
  </link>
  <link name="right_link_5">
    <visual>
      <origin rpy="0 0 0" xyz="0 0 0"/>
      <geometry>
        <mesh filename="package://asystr_sensible_model/meshes/visual/RPR/differential.dae" scale="0.001 0.001 0.001"/>
      </geometry>
    </visual>
    <collision>
      <origin rpy="0 0 0" xyz="0 0 0"/>
      <geometry>
        <mesh filename="package://asystr_sensible_model/meshes/collision/RPR/differential.stl" scale="0.001 0.001 0.001"/>
      </geometry>
    </collision>
    <inertial>
      <origin rpy="0 0 0" xyz="0 0 0"/>
      <mass value="0.01"/>
      <inertia ixx="0.01" ixy="0.0" ixz="0.0" iyy="0.01" iyz="0.0" izz="0.01"/>
    </inertial>
  </link>
  <link name="right_link_6">
    <visual>
      <origin rpy="0 0 0" xyz="0 0 0"/>
      <geometry>
        <mesh filename="package://asystr_sensible_model/meshes/visual/RPR/flange.dae" scale="0.001 0.001 0.001"/>
      </geometry>
    </visual>
    <collision>
      <origin rpy="0 0 0" xyz="0 0 0"/>
      <geometry>
        <mesh filename="package://asystr_sensible_model/meshes/collision/RPR/flange.stl" scale="0.001 0.001 0.001"/>
      </geometry>
    </collision>
    <inertial>
      <origin rpy="0 0 0" xyz="0 0 0"/>
      <mass value="0.01"/>
      <inertia ixx="0.01" ixy="0.0" ixz="0.0" iyy="0.01" iyz="0.0" izz="0.01"/>
    </inertial>
  </link>
  <!-- Create Joints -->
  <joint name="right_joint_4" type="continuous">
    <parent link="right_wrist_adapter"/>
    <child link="right_link_4"/>
    <origin rpy="0 -0.0 1.5707963" xyz="0 -0.0 0.088"/>
    <axis xyz="0 0 1"/>
    <limit effort="100.0" lower="-3.141592653589793" upper="3.141592653589793" velocity="100.0"/>
  </joint>
  <joint name="right_joint_5" type="revolute">
    <parent link="right_link_4"/>
    <child link="right_link_5"/>
    <origin rpy="1.5707963 0.0 0.0" xyz="0 0.0 0.0"/>
    <axis xyz="0 0 1"/>
    <limit effort="100.0" lower="-2.0943951023931953" upper="2.0943951023931953" velocity="100.0"/>
  </joint>
  <joint name="right_joint_6" type="continuous">
    <parent link="right_link_5"/>
    <child link="right_link_6"/>
    <origin rpy="-1.5707963 -0.0 0.0" xyz="0 0.06949999999999998 1.8622453126594902e-09"/>
    <axis xyz="0 0 1"/>
    <limit effort="100.0" lower="-3.141592653589793" upper="3.141592653589793" velocity="100.0"/>
  </joint>
  <joint name="sherpa_body_to_right" type="fixed">
    <parent link="sherpa_body"/>
    <child link="right_base_link"/>
    <origin rpy="3.141592653589793 0 0" xyz="0.0 -0.28 0.575"/>
  </joint>
</robot>
